Workbook

Sheet Sheet1
A1: Student_ID | B1: Name | C1: Age | D1: Gender | E1: Department | F1: Semester | G1: City | H1: GPA | I1: Attendance
A2: S001 | B2: Ali Khan | C2: 20 | D2: Male | E2: Computer Science | F2: 5 | G2: Lahore | H2: 3.55 | I2: 92
A3: S002 | B3: Ayesha Ahmed | C3: 21 | D3: Female | E3: Software Engineering | F3: 6 | G3: Karachi | H3: 3.8 | I3: 0.88
A4: S003 | B4: Hassan Raza | C4: 22 | D4: Male | E4: Information Technology | F4: 7 | G4: Islamabad | H4: 3.21 | I4: 0.85
A5: S004 | B5: Sana zaman | C5: 20 | D5: Female | E5: Computer Science | F5: 5 | G5: Faisalabad | H5: 3.97 | I5: 0.95
A6: S005 | B6: Umar Farooq | C6: 21 | D6: Male | E6: Data Science | F6: 6 | G6: Multan | H6: 3.38 | I6: 0.81
A7: S006 | B7: Zainab Tariq | C7: 22 | D7: Female | E7: IT | F7: 7 | G7: Rawalpindi | H7: 3.76 | I7: 0.9 | M7: Transpose of data
A8: S007 | B8: Bilal Aslam | C8: 20 | D8: Male | E8: Computer Science | F8: 5 | G8: Sialkot | H8: 3.04 | I8: 0.76
A9: S008 | B9: Maryam Noor | C9: 21 | D9: Female | E9: Software Engineering | F9: 6 | G9: Gujranwala | H9: 4 | I9: 0.96
A10: S009 | B10: Ahmed Hassan | C10: 23 | D10: Male | E10: Information Technology | F10: 8 | G10: Peshawar | H10: 3.27 | I10: 0.82
A11: S010 | B11: Laiba Khan | C11: 20 | D11: Female | E11: Data Science | F11: 5 | G11: Lahore | H11: 3.64 | I11: 0.91
A12: S011 | B12: Usman Ali | C12: 21 | D12: Male | E12: Computer Science | F12: 6 | G12: Karachi | H12: 3.58 | I12: 0.89
A13: S012 | B13: Hina Akram | C13: 22 | D13: Female | E13: IT | F13: 7 | G13: Islamabad | H13: 3.89 | I13: 0.94
A14: S013 | B14: Zain | C14: 20 | D14: Male | E14: Computer Science | F14: 5 | G14: Lahore | H14: 3.29 | I14: 0.87
A15: S014 | B15: Sadia Iqbal | C15: 23 | D15: Female | E15: Software Engineering | F15: 6 | G15: Faisalabad | H15: 3.5 | I15: 0.84 | M15: Student_ID | N15: S002 | O15: S004 | P15: S006 | Q15: S008 | R15: S010 | S15: S012 | T15: S014 | U15: S016 | V15: S018 | W15: S020 | X15: S022 | Y15: S024 | Z15: S026 | AA15: S028 | AB15: S030 | AC15: S032 | AD15: S034 | AE15: S036 | AF15: S038 | AG15: S040 | AH15: S042 | AI15: S044 | AJ15: S045 | AK15: S047 | AL15: S049 | AM15: S052 | AN15: S054 | AO15: S056 | AP15: S058 | AQ15: S060 | AR15: S062 | AS15: S063 | AT15: S065 | AU15: S067 | AV15: S069 | AW15: S072 | AX15: S074 | AY15: S076 | AZ15: S078 | BA15: S080 | BB15: S082 | BC15: S084 | BD15: S086 | BE15: S088 | BF15: S090 | BG15: S092 | BH15: S094 | BI15: S095 | BJ15: S097 | BK15: S099
A16: S015 | B16: Arslan Shah | C16: 21 | D16: Male | E16: Data Science | F16: 6 | G16: Multan | H16: 3.18 | I16: 0.79 | M16: Name | N16: Ayesha Ahmed | O16: Sana Malik | P16: Zainab Tariq | Q16: Maryam Noor | R16: Laiba Khan | S16: Hina Akram | T16: Sadia Iqbal | U16: Noor Fatima | V16: Mahnoor Ali | W16: Ayesha Ahmed | X16: Mehwish Khan | Y16: Rabia Noor | Z16: Nida Aslam | AA16: Amna Tariq | AB16: Areeba Malik | AC16: Eman Fatima | AD16: Sana Malik | AE16: Maria | AF16: Hoor Fatima | AG16: Anum Shah | AH16: Maria Noor | AI16: Areeba Malik | AJ16: Dua Khan | AK16: Komal Tariq | AL16: Minal Noor | AM16: Ayesha Ahmed | AN16: Sana Malik | AO16: Zainab Tariq | AP16: Maryam Noor | AQ16: Laiba Khan | AR16: Hina Akram | AS16: Aiman Ali | AT16: Fiza Noor | AU16: Noor Fatima | AV16: Mahnoor Ali | AW16: Dua Khan | AX16: Komal Tariq | AY16: Minal Noor | AZ16: Rabia Noor | BA16: Nida Aslam | BB16: Amna Tariq | BC16: Areeba Malik | BD16: Eman Fatima | BE16: Hoor Fatima | BF16: Anum Shah | BG16: Maria Noor | BH16: Areeba Malik | BI16: Dua Khan | BJ16: Komal Tariq | BK16: Minal Noor
A17: S016 | B17: Noor Fatima | C17: 20 | D17: Female | E17: Computer Science | F17: 5 | G17: Multan | H17: 3.86 | I17: 0.93 | M17: Age | N17: 21 | O17: 20 | P17: 22 | Q17: 21 | R17: 20 | S17: 22 | T17: 23 | U17: 20 | V17: 21 | W17: 21 | X17: 22 | Y17: 20 | Z17: 21 | AA17: 22 | AB17: 20 | AC17: 20 | AD17: 20 | AE17: 22 | AF17: 21 | AG17: 20 | AH17: 20 | AI17: 20 | AJ17: 22 | AK17: 20 | AL17: 21 | AM17: 21 | AN17: 20 | AO17: 22 | AP17: 21 | AQ17: 20 | AR17: 22 | AS17: 20 | AT17: 22 | AU17: 20 | AV17: 21 | AW17: 22 | AX17: 20 | AY17: 21 | AZ17: 20 | BA17: 21 | BB17: 22 | BC17: 20 | BD17: 20 | BE17: 21 | BF17: 20 | BG17: 20 | BH17: 20 | BI17: 22 | BJ17: 20 | BK17: 21
A18: S017 | B18: Imran Butt | C18: 22 | D18: Male | E18: Information Technology | F18: 7 | G18: Sialkot | H18: 3.54 | I18: 0.88 | M18: Gender | N18: Female | O18: Female | P18: Female | Q18: Female | R18: Female | S18: Female | T18: Female | U18: Female | V18: Female | W18: Female | X18: Female | Y18: Female | Z18: Female | AA18: Female | AB18: Female | AC18: Female | AD18: Female | AE18: Female | AF18: Female | AG18: Female | AH18: Female | AI18: Female | AJ18: Female | AK18: Female | AL18: Female | AM18: Female | AN18: Female | AO18: Female | AP18: Female | AQ18: Female | AR18: Female | AS18: Female | AT18: Female | AU18: Female | AV18: Female | AW18: Female | AX18: Female | AY18: Female | AZ18: Female | BA18: Female | BB18: Female | BC18: Female | BD18: Female | BE18: Female | BF18: Female | BG18: Female | BH18: Female | BI18: Female | BJ18: Female | BK18: Female
A19: S018 | B19: Mahnoor Ali | C19: 21 | D19: Female | E19: Data Science | F19: 6 | G19: Gujranwala | H19: 3.75 | I19: 0.88 | M19: Department | N19: Software Engineering | O19: Computer Science | P19: IT | Q19: Software Engineering | R19: Data Science | S19: IT | T19: Software Engineering | U19: Computer Science | V19: Data Science | W19: Software Engineering | X19: Computer Science | Y19: Information Technology | Z19: Computer Science | AA19: Software Engineering | AB19: Data Science | AC19: Computer Science | AD19: Computer Science | AE19: Computer Science | AF19: Computer Science | AG19: Computer Science | AH19: Computer Science | AI19: Computer Science | AJ19: Computer Science | AK19: Computer Science | AL19: Computer Science | AM19: Computer Science | AN19: Computer Science | AO19: Computer Science | AP19: Computer Science | AQ19: Computer Science | AR19: Computer Science | AS19: Computer Science | AT19: Computer Science | AU19: Computer Science | AV19: Computer Science | AW19: Computer Science | AX19: Computer Science | AY19: Computer Science | AZ19: Computer Science | BA19: Computer Science | BB19: Computer Science | BC19: Computer Science | BD19: Computer Science | BE19: Computer Science | BF19: Computer Science | BG19: Computer Science | BH19: Computer Science | BI19: Computer Science | BJ19: Computer Science | BK19: Computer Science
A20: S019 | B20: Ali Khan | C20: 20 | D20: Male | E20: Computer Science | F20: 5 | G20: Lahore | H20: 3.54 | I20: 0.92 | M20: Semester | N20: 6 | O20: 5 | P20: 7 | Q20: 6 | R20: 5 | S20: 7 | T20: 6 | U20: 5 | V20: 6 | W20: 6 | X20: 7 | Y20: 5 | Z20: 6 | AA20: 7 | AB20: 5 | AC20: 5 | AD20: 5 | AE20: 7 | AF20: 6 | AG20: 5 | AH20: 5 | AI20: 5 | AJ20: 7 | AK20: 5 | AL20: 6 | AM20: 6 | AN20: 5 | AO20: 7 | AP20: 6 | AQ20: 5 | AR20: 7 | AS20: 5 | AT20: 7 | AU20: 5 | AV20: 6 | AW20: 7 | AX20: 5 | AY20: 6 | AZ20: 5 | BA20: 6 | BB20: 7 | BC20: 5 | BD20: 5 | BE20: 6 | BF20: 5 | BG20: 5 | BH20: 5 | BI20: 7 | BJ20: 5 | BK20: 6
A21: S020 | B21: Ayesha Ahmed | C21: 21 | D21: Female | E21: Software Engineering | F21: 6 | G21: Karachi | H21: 3.8 | I21: 0.88 | M21: City | N21: Karachi | O21: Faisalabad | P21: Rawalpindi | Q21: Gujranwala | R21: Lahore | S21: Islamabad | T21: Faisalabad | U21: Multan | V21: Gujranwala | W21: Karachi | X21: Multan | Y21: Karachi | Z21: Sialkot | AA21: Lahore | AB21: Islamabad | AC21: Lahore | AD21: Faisalabad | AE21: Multan | AF21: Lahore | AG21: Faisalabad | AH21: Islamabad | AI21: Islamabad | AJ21: Rawalpindi | AK21: Multan | AL21: Lahore | AM21: Karachi | AN21: Faisalabad | AO21: Rawalpindi | AP21: Gujranwala | AQ21: Lahore | AR21: Islamabad | AS21: Lahore | AT21: Multan | AU21: Lahore | AV21: Gujranwala | AW21: Rawalpindi | AX21: Multan | AY21: Lahore | AZ21: Karachi | BA21: Sialkot | BB21: Lahore | BC21: Islamabad | BD21: Lahore | BE21: Lahore | BF21: Faisalabad | BG21: Islamabad | BH21: Islamabad | BI21: Rawalpindi | BJ21: Multan | BK21: Lahore
A22: S021 | B22: Hamza Tariq | C22: 20 | D22: Male | E22: Cyber Security | F22: 5 | G22: Lahore | H22: 3.23 | I22: 0.8 | M22: GPA | N22: 3.8 | O22: 3.97 | P22: 3.76 | Q22: 4 | R22: 3.64 | S22: 3.89 | T22: 3.5 | U22: 3.86 | V22: 3.75 | W22: 3.8 | X22: 3.67 | Y22: 4.03 | Z22: 3.82 | AA22: 3.91 | AB22: 3.78 | AC22: 4.05 | AD22: 3.97 | AE22: 3.61 | AF22: 3.77 | AG22: 3.38 | AH22: 3.87 | AI22: 3.78 | AJ22: 3.56 | AK22: 4.02 | AL22: 3.81 | AM22: 3.8 | AN22: 3.97 | AO22: 3.76 | AP22: 4 | AQ22: 3.64 | AR22: 3.89 | AS22: 3.69 | AT22: 3.92 | AU22: 3.86 | AV22: 3.75 | AW22: 3.56 | AX22: 4.02 | AY22: 3.81 | AZ22: 4.03 | BA22: 3.82 | BB22: 3.91 | BC22: 3.78 | BD22: 4.05 | BE22: 3.77 | BF22: 3.53 | BG22: 3.87 | BH22: 3.78 | BI22: 3.56 | BJ22: 4.02 | BK22: 3.81
A23: S022 | B23: Mehwish Khan | C23: 22 | D23: Female | E23: Computer Science | F23: 7 | G23: Multan | H23: 3.67 | I23: 0.9 | M23: Attendance | N23: 0.88 | O23: 0.95 | P23: 0.9 | Q23: 0.96 | R23: 0.91 | S23: 0.94 | T23: 0.84 | U23: 0.93 | V23: 0.88 | W23: 0.88 | X23: 0.9 | Y23: 0.98 | Z23: 0.92 | AA23: 0.95 | AB23: 0.94 | AC23: 0.99 | AD23: 0.95 | AE23: 0.89 | AF23: 0.91 | AG23: 0.9 | AH23: 0.94 | AI23: 0.94 | AJ23: 0.88 | AK23: 0.97 | AL23: 0.93 | AM23: 0.88 | AN23: 0.95 | AO23: 0.9 | AP23: 0.96 | AQ23: 0.91 | AR23: 0.94 | AS23: 0.9 | AT23: 0.95 | AU23: 0.93 | AV23: 0.89 | AW23: 0.88 | AX23: 0.97 | AY23: 0.93 | AZ23: 0.98 | BA23: 0.92 | BB23: 0.95 | BC23: 0.94 | BD23: 0.99 | BE23: 0.91 | BF23: 0.9 | BG23: 0.94 | BH23: 0.94 | BI23: 0.88 | BJ23: 0.97 | BK23: 0.93
A24: S023 | B24: Danish Malik | C24: 21 | D24: Male | E24: Software Engineering | F24: 6 | G24: Faisalabad | H24: 2.97 | I24: 0.72
A25: S024 | B25: Rabia Noor | C25: 20 | D25: Female | E25: Information Technology | F25: 5 | G25: Karachi | H25: 4.03 | I25: 0.98
A26: S025 | B26: Fahad Ali | C26: 22 | D26: Male | E26: Data Science | F26: 7 | G26: Lahore | H26: 3.7 | I26: 0.91
A27: S026 | B27: Nida Aslam | C27: 21 | D27: Female | E27: Computer Science | F27: 6 | G27: Sialkot | H27: 3.82 | I27: 0.92
A28: S027 | B28: Zeeshan Ahmed | C28: 20 | D28: Male | E28: Cyber Security | F28: 5 | G28: Rawalpindi | H28: 3.06 | I28: 0.77
A29: S028 | B29: Amna Tariq | C29: 22 | D29: Female | E29: Software Engineering | F29: 7 | G29: Lahore | H29: 3.91 | I29: 0.95
A30: S029 | B30: Talha Khan | C30: 21 | D30: Male | E30: Computer Science | F30: 6 | G30: Peshawar | H30: 3.27 | I30: 0.86
A31: S030 | B31: Areeba Malik | C31: 20 | D31: Female | E31: Data Science | F31: 5 | G31: Islamabad | H31: 3.78 | I31: 0.94
A32: S031 | B32: Saad Raza | C32: 23 | D32: Male | E32: Information Technology | F32: 8 | G32: Karachi | H32: 3.17 | I32: 0.83
A33: S032 | B33: Eman Fatima | C33: 20 | D33: Female | E33: Computer Science | F33: 5 | G33: Lahore | H33: 4.05 | I33: 0.99
A34: S033 | B34: Hassan Raza | C34: 22 | D34: Male | E34: Information Technology | F34: 7 | G34: Islamabad | H34: 3.21 | I34: 0.85 | R34: 7 | S34: 92 | T34: 61
A35: S034 | B35: Sana zaman | C35: 20 | D35: Female | E35: Computer Science | F35: 5 | G35: Faisalabad | H35: 3.97 | I35: 0.95
A36: S035 | B36: Ali Hassan | C36: 21 | D36: Male | E36: Software Engineering | F36: 6 | G36: Lahore | H36: 3.43 | I36: 0.87 | R36: 90 | S36: 86 | T36: 32
A37: S036 | B37: Maria | C37: 22 | D37: Female | E37: Computer Science | F37: 7 | G37: Multan | H37: 3.61 | I37: 0.89
A38: S037 | B38: Ahmed Ali | C38: 23 | D38: Male | E38: Computer Science | F38: 5 | G38: Karachi | H38: 3.2 | I38: 0.78 | R38: 16 | S38: 29 | T38: 57
A39: S038 | B39: Hoor Fatima | C39: 21 | D39: Female | E39: Computer Science | F39: 6 | G39: Lahore | H39: 3.77 | I39: 0.91
A40: S039 | B40: Ubaid Khan | C40: 22 | D40: Male | E40: Data Science | F40: 7 | G40: Karachi | H40: 3.32 | I40: 0.82 | R40: 31 | S40: 75 | T40: 75
...

Sheet Sheet2
A1: =Sheet1!A1 -> Student_ID | B1: =Sheet1!B1 -> Name | C1: =Sheet1!C1 -> Age | D1: =Sheet1!D1 -> Gender | E1: =Sheet1!E1 -> Department | F1: =Sheet1!F1 -> Semester | G1: =Sheet1!G1 -> City | H1: =Sheet1!H1 -> GPA | I1: =Sheet1!I1 -> Attendance
A2: =Sheet1!A3 -> S002 | B2: =Sheet1!B3 -> Ayesha Ahmed | C2: =Sheet1!C3 -> 21 | D2: =Sheet1!D3 -> Female | E2: =Sheet1!E3 -> Software Engineering | F2: =Sheet1!F3 -> 6 | G2: =Sheet1!G3 -> Karachi | H2: =Sheet1!H3 -> 3.8 | I2: =Sheet1!I3 -> 0.88
A3: =Sheet1!A5 -> S004 | B3: =Sheet1!B5 -> Sana zaman | C3: =Sheet1!C5 -> 20 | D3: =Sheet1!D5 -> Female | E3: =Sheet1!E5 -> Computer Science | F3: =Sheet1!F5 -> 5 | G3: =Sheet1!G5 -> Faisalabad | H3: =Sheet1!H5 -> 3.97 | I3: =Sheet1!I5 -> 0.95
A4: =Sheet1!A7 -> S006 | B4: =Sheet1!B7 -> Zainab Tariq | C4: =Sheet1!C7 -> 22 | D4: =Sheet1!D7 -> Female | E4: =Sheet1!E7 -> IT | F4: =Sheet1!F7 -> 7 | G4: =Sheet1!G7 -> Rawalpindi | H4: =Sheet1!H7 -> 3.76 | I4: =Sheet1!I7 -> 0.9
A5: =Sheet1!A9 -> S008 | B5: =Sheet1!B9 -> Maryam Noor | C5: =Sheet1!C9 -> 21 | D5: =Sheet1!D9 -> Female | E5: =Sheet1!E9 -> Software Engineering | F5: =Sheet1!F9 -> 6 | G5: =Sheet1!G9 -> Gujranwala | H5: =Sheet1!H9 -> 4 | I5: =Sheet1!I9 -> 0.96
A6: =Sheet1!A11 -> S010 | B6: =Sheet1!B11 -> Laiba Khan | C6: =Sheet1!C11 -> 20 | D6: =Sheet1!D11 -> Female | E6: =Sheet1!E11 -> Data Science | F6: =Sheet1!F11 -> 5 | G6: =Sheet1!G11 -> Lahore | H6: =Sheet1!H11 -> 3.64 | I6: =Sheet1!I11 -> 0.91
A7: =Sheet1!A13 -> S012 | B7: =Sheet1!B13 -> Hina Akram | C7: =Sheet1!C13 -> 22 | D7: =Sheet1!D13 -> Female | E7: =Sheet1!E13 -> IT | F7: =Sheet1!F13 -> 7 | G7: =Sheet1!G13 -> Islamabad | H7: =Sheet1!H13 -> 3.89 | I7: =Sheet1!I13 -> 0.94
A8: =Sheet1!A15 -> S014 | B8: =Sheet1!B15 -> Sadia Iqbal | C8: =Sheet1!C15 -> 23 | D8: =Sheet1!D15 -> Female | E8: =Sheet1!E15 -> Software Engineering | F8: =Sheet1!F15 -> 6 | G8: =Sheet1!G15 -> Faisalabad | H8: =Sheet1!H15 -> 3.5 | I8: =Sheet1!I15 -> 0.84
A9: =Sheet1!A17 -> S016 | B9: =Sheet1!B17 -> Noor Fatima | C9: =Sheet1!C17 -> 20 | D9: =Sheet1!D17 -> Female | E9: =Sheet1!E17 -> Computer Science | F9: =Sheet1!F17 -> 5 | G9: =Sheet1!G17 -> Multan | H9: =Sheet1!H17 -> 3.86 | I9: =Sheet1!I17 -> 0.93
A10: =Sheet1!A19 -> S018 | B10: =Sheet1!B19 -> Mahnoor Ali | C10: =Sheet1!C19 -> 21 | D10: =Sheet1!D19 -> Female | E10: =Sheet1!E19 -> Data Science | F10: =Sheet1!F19 -> 6 | G10: =Sheet1!G19 -> Gujranwala | H10: =Sheet1!H19 -> 3.75 | I10: =Sheet1!I19 -> 0.88
A11: =Sheet1!A21 -> S020 | B11: =Sheet1!B21 -> Ayesha Ahmed | C11: =Sheet1!C21 -> 21 | D11: =Sheet1!D21 -> Female | E11: =Sheet1!E21 -> Software Engineering | F11: =Sheet1!F21 -> 6 | G11: =Sheet1!G21 -> Karachi | H11: =Sheet1!H21 -> 3.8 | I11: =Sheet1!I21 -> 0.88
A12: =Sheet1!A23 -> S022 | B12: =Sheet1!B23 -> Mehwish Khan | C12: =Sheet1!C23 -> 22 | D12: =Sheet1!D23 -> Female | E12: =Sheet1!E23 -> Computer Science | F12: =Sheet1!F23 -> 7 | G12: =Sheet1!G23 -> Multan | H12: =Sheet1!H23 -> 3.67 | I12: =Sheet1!I23 -> 0.9
A13: =Sheet1!A25 -> S024 | B13: =Sheet1!B25 -> Rabia Noor | C13: =Sheet1!C25 -> 20 | D13: =Sheet1!D25 -> Female | E13: =Sheet1!E25 -> Information Technology | F13: =Sheet1!F25 -> 5 | G13: =Sheet1!G25 -> Karachi | H13: =Sheet1!H25 -> 4.03 | I13: =Sheet1!I25 -> 0.98
A14: =Sheet1!A27 -> S026 | B14: =Sheet1!B27 -> Nida Aslam | C14: =Sheet1!C27 -> 21 | D14: =Sheet1!D27 -> Female | E14: =Sheet1!E27 -> Computer Science | F14: =Sheet1!F27 -> 6 | G14: =Sheet1!G27 -> Sialkot | H14: =Sheet1!H27 -> 3.82 | I14: =Sheet1!I27 -> 0.92
A15: =Sheet1!A29 -> S028 | B15: =Sheet1!B29 -> Amna Tariq | C15: =Sheet1!C29 -> 22 | D15: =Sheet1!D29 -> Female | E15: =Sheet1!E29 -> Software Engineering | F15: =Sheet1!F29 -> 7 | G15: =Sheet1!G29 -> Lahore | H15: =Sheet1!H29 -> 3.91 | I15: =Sheet1!I29 -> 0.95
A16: =Sheet1!A31 -> S030 | B16: =Sheet1!B31 -> Areeba Malik | C16: =Sheet1!C31 -> 20 | D16: =Sheet1!D31 -> Female | E16: =Sheet1!E31 -> Data Science | F16: =Sheet1!F31 -> 5 | G16: =Sheet1!G31 -> Islamabad | H16: =Sheet1!H31 -> 3.78 | I16: =Sheet1!I31 -> 0.94
A17: =Sheet1!A33 -> S032 | B17: =Sheet1!B33 -> Eman Fatima | C17: =Sheet1!C33 -> 20 | D17: =Sheet1!D33 -> Female | E17: =Sheet1!E33 -> Computer Science | F17: =Sheet1!F33 -> 5 | G17: =Sheet1!G33 -> Lahore | H17: =Sheet1!H33 -> 4.05 | I17: =Sheet1!I33 -> 0.99
A18: =Sheet1!A35 -> S034 | B18: =Sheet1!B35 -> Sana zaman | C18: =Sheet1!C35 -> 20 | D18: =Sheet1!D35 -> Female | E18: =Sheet1!E35 -> Computer Science | F18: =Sheet1!F35 -> 5 | G18: =Sheet1!G35 -> Faisalabad | H18: =Sheet1!H35 -> 3.97 | I18: =Sheet1!I35 -> 0.95
A19: =Sheet1!A37 -> S036 | B19: =Sheet1!B37 -> Maria | C19: =Sheet1!C37 -> 22 | D19: =Sheet1!D37 -> Female | E19: =Sheet1!E37 -> Computer Science | F19: =Sheet1!F37 -> 7 | G19: =Sheet1!G37 -> Multan | H19: =Sheet1!H37 -> 3.61 | I19: =Sheet1!I37 -> 0.89
A20: =Sheet1!A39 -> S038 | B20: =Sheet1!B39 -> Hoor Fatima | C20: =Sheet1!C39 -> 21 | D20: =Sheet1!D39 -> Female | E20: =Sheet1!E39 -> Computer Science | F20: =Sheet1!F39 -> 6 | G20: =Sheet1!G39 -> Lahore | H20: =Sheet1!H39 -> 3.77 | I20: =Sheet1!I39 -> 0.91
A21: =Sheet1!A41 -> S040 | B21: =Sheet1!B41 -> Anum Shah | C21: =Sheet1!C41 -> 20 | D21: =Sheet1!D41 -> Female | E21: =Sheet1!E41 -> Computer Science | F21: =Sheet1!F41 -> 5 | G21: =Sheet1!G41 -> Faisalabad | H21: =Sheet1!H41 -> 3.38 | I21: =Sheet1!I41 -> 0.9
A22: =Sheet1!A43 -> S042 | B22: =Sheet1!B43 -> Maria Noor | C22: =Sheet1!C43 -> 20 | D22: =Sheet1!D43 -> Female | E22: =Sheet1!E43 -> Computer Science | F22: =Sheet1!F43 -> 5 | G22: =Sheet1!G43 -> Islamabad | H22: =Sheet1!H43 -> 3.87 | I22: =Sheet1!I43 -> 0.94
A23: =Sheet1!A45 -> S044 | B23: =Sheet1!B45 -> Areeba Malik | C23: =Sheet1!C45 -> 20 | D23: =Sheet1!D45 -> Female | E23: =Sheet1!E45 -> Computer Science | F23: =Sheet1!F45 -> 5 | G23: =Sheet1!G45 -> Islamabad | H23: =Sheet1!H45 -> 3.78 | I23: =Sheet1!I45 -> 0.94
A24: =Sheet1!A46 -> S045 | B24: =Sheet1!B46 -> Dua Khan | C24: =Sheet1!C46 -> 22 | D24: =Sheet1!D46 -> Female | E24: =Sheet1!E46 -> Computer Science | F24: =Sheet1!F46 -> 7 | G24: =Sheet1!G46 -> Rawalpindi | H24: =Sheet1!H46 -> 3.56 | I24: =Sheet1!I46 -> 0.88
A25: =Sheet1!A48 -> S047 | B25: =Sheet1!B48 -> Komal Tariq | C25: =Sheet1!C48 -> 20 | D25: =Sheet1!D48 -> Female | E25: =Sheet1!E48 -> Computer Science | F25: =Sheet1!F48 -> 5 | G25: =Sheet1!G48 -> Multan | H25: =Sheet1!H48 -> 4.02 | I25: =Sheet1!I48 -> 0.97
A26: =Sheet1!A50 -> S049 | B26: =Sheet1!B50 -> Minal Noor | C26: =Sheet1!C50 -> 21 | D26: =Sheet1!D50 -> Female | E26: =Sheet1!E50 -> Computer Science | F26: =Sheet1!F50 -> 6 | G26: =Sheet1!G50 -> Lahore | H26: =Sheet1!H50 -> 3.81 | I26: =Sheet1!I50 -> 0.93
A27: =Sheet1!A53 -> S052 | B27: =Sheet1!B53 -> Ayesha Ahmed | C27: =Sheet1!C53 -> 21 | D27: =Sheet1!D53 -> Female | E27: =Sheet1!E53 -> Computer Science | F27: =Sheet1!F53 -> 6 | G27: =Sheet1!G53 -> Karachi | H27: =Sheet1!H53 -> 3.8 | I27: =Sheet1!I53 -> 0.88
A28: =Sheet1!A55 -> S054 | B28: =Sheet1!B55 -> Sana Malik | C28: =Sheet1!C55 -> 20 | D28: =Sheet1!D55 -> Female | E28: =Sheet1!E55 -> Computer Science | F28: =Sheet1!F55 -> 5 | G28: =Sheet1!G55 -> Faisalabad | H28: =Sheet1!H55 -> 3.97 | I28: =Sheet1!I55 -> 0.95
A29: =Sheet1!A57 -> S056 | B29: =Sheet1!B57 -> Zainab Tariq | C29: =Sheet1!C57 -> 22 | D29: =Sheet1!D57 -> Female | E29: =Sheet1!E57 -> Computer Science | F29: =Sheet1!F57 -> 7 | G29: =Sheet1!G57 -> Rawalpindi | H29: =Sheet1!H57 -> 3.76 | I29: =Sheet1!I57 -> 0.9
A30: =Sheet1!A59 -> S058 | B30: =Sheet1!B59 -> Maryam Noor | C30: =Sheet1!C59 -> 21 | D30: =Sheet1!D59 -> Female | E30: =Sheet1!E59 -> Computer Science | F30: =Sheet1!F59 -> 6 | G30: =Sheet1!G59 -> Gujranwala | H30: =Sheet1!H59 -> 4 | I30: =Sheet1!I59 -> 0.96
A31: =Sheet1!A61 -> S060 | B31: =Sheet1!B61 -> Laiba Khan | C31: =Sheet1!C61 -> 20 | D31: =Sheet1!D61 -> Female | E31: =Sheet1!E61 -> Computer Science | F31: =Sheet1!F61 -> 5 | G31: =Sheet1!G61 -> Lahore | H31: =Sheet1!H61 -> 3.64 | I31: =Sheet1!I61 -> 0.91
A32: =Sheet1!A63 -> S062 | B32: =Sheet1!B63 -> Hina Akram | C32: =Sheet1!C63 -> 22 | D32: =Sheet1!D63 -> Female | E32: =Sheet1!E63 -> Computer Science | F32: =Sheet1!F63 -> 7 | G32: =Sheet1!G63 -> Islamabad | H32: =Sheet1!H63 -> 3.89 | I32: =Sheet1!I63 -> 0.94
A33: =Sheet1!A64 -> S063 | B33: =Sheet1!B64 -> Aiman Ali | C33: =Sheet1!C64 -> 20 | D33: =Sheet1!D64 -> Female | E33: =Sheet1!E64 -> Computer Science | F33: =Sheet1!F64 -> 5 | G33: =Sheet1!G64 -> Lahore | H33: =Sheet1!H64 -> 3.69 | I33: =Sheet1!I64 -> 0.9
A34: =Sheet1!A66 -> S065 | B34: =Sheet1!B66 -> Fiza Noor | C34: =Sheet1!C66 -> 22 | D34: =Sheet1!D66 -> Female | E34: =Sheet1!E66 -> Computer Science | F34: =Sheet1!F66 -> 7 | G34: =Sheet1!G66 -> Multan | H34: =Sheet1!H66 -> 3.92 | I34: =Sheet1!I66 -> 0.95
A35: =Sheet1!A68 -> S067 | B35: =Sheet1!B68 -> Noor Fatima | C35: =Sheet1!C68 -> 20 | D35: =Sheet1!D68 -> Female | E35: =Sheet1!E68 -> Computer Science | F35: =Sheet1!F68 -> 5 | G35: =Sheet1!G68 -> Lahore | H35: =Sheet1!H68 -> 3.86 | I35: =Sheet1!I68 -> 0.93
A36: =Sheet1!A70 -> S069 | B36: =Sheet1!B70 -> Mahnoor Ali | C36: =Sheet1!C70 -> 21 | D36: =Sheet1!D70 -> Female | E36: =Sheet1!E70 -> Computer Science | F36: =Sheet1!F70 -> 6 | G36: =Sheet1!G70 -> Gujranwala | H36: =Sheet1!H70 -> 3.75 | I36: =Sheet1!I70 -> 0.89
A37: =Sheet1!A73 -> S072 | B37: =Sheet1!B73 -> Dua Khan | C37: =Sheet1!C73 -> 22 | D37: =Sheet1!D73 -> Female | E37: =Sheet1!E73 -> Computer Science | F37: =Sheet1!F73 -> 7 | G37: =Sheet1!G73 -> Rawalpindi | H37: =Sheet1!H73 -> 3.56 | I37: =Sheet1!I73 -> 0.88
A38: =Sheet1!A75 -> S074 | B38: =Sheet1!B75 -> Komal Tariq | C38: =Sheet1!C75 -> 20 | D38: =Sheet1!D75 -> Female | E38: =Sheet1!E75 -> Computer Science | F38: =Sheet1!F75 -> 5 | G38: =Sheet1!G75 -> Multan | H38: =Sheet1!H75 -> 4.02 | I38: =Sheet1!I75 -> 0.97
A39: =Sheet1!A77 -> S076 | B39: =Sheet1!B77 -> Minal Noor | C39: =Sheet1!C77 -> 21 | D39: =Sheet1!D77 -> Female | E39: =Sheet1!E77 -> Computer Science | F39: =Sheet1!F77 -> 6 | G39: =Sheet1!G77 -> Lahore | H39: =Sheet1!H77 -> 3.81 | I39: =Sheet1!I77 -> 0.93
A40: =Sheet1!A79 -> S078 | B40: =Sheet1!B79 -> Rabia Noor | C40: =Sheet1!C79 -> 20 | D40: =Sheet1!D79 -> Female | E40: =Sheet1!E79 -> Computer Science | F40: =Sheet1!F79 -> 5 | G40: =Sheet1!G79 -> Karachi | H40: =Sheet1!H79 -> 4.03 | I40: =Sheet1!I79 -> 0.98
...
